<?xml version="1.0"?>
<robot name="foldable_robot">

  <material name="red">
    <color rgba="1 0 0 0.3"/>
  </material>

  <material name="blue">
    <color rgba="0 0 1 0.3"/>
  </material>

  <link name="cube1">
    <pose> 0 0 0 0 0 0</pose>

    <visual>
      <origin rpy = "0 0 0" xyz = "0 0 0"/>
      <geometry>
        <box size = "0.05 0.05 0.05"/>
      </geometry>
      <material name = "red"/>
    </visual>

    <collision>
      <origin rpy = "0 0 0" xyz = "0 0 0"/>
      <geometry>
        <box size = "0.05 0.05 0.05"/>
      </geometry>
    </collision>

    <inertial>
    	<mass value = "0.1" />
    	<origin rpy = "0 0 0" xyz = "0 0 0"/>
    	<inertia ixx = "0.0000416667" ixy = "0" ixz = "0" iyy = "0.0000416667" iyz = "0" izz = "0.0000416667" />
    </inertial>
    </link>

  <link name="cube2">
    <pose> 0 0 0 0 0 0</pose>

    <visual>
      <origin rpy = "0 0 0" xyz = "0.025 0 0.025"/>
      <geometry>
        <box size = "0.05 0.05 0.05"/>
      </geometry>
      <material name = "blue"/>
    </visual>

    <collision>
      <origin rpy = "0 0 0" xyz = "0.025 0 0.025"/>
      <geometry>
        <box size = "0.05 0.05 0.05"/>
      </geometry>
    </collision>

      <inertial>
    	<mass value = "0.1" />
    	<origin rpy = "0 0 0" xyz = "0 0 0"/>
    	<inertia ixx = "0.0000416667" ixy = "0" ixz = "0" iyy = "0.0000416667" iyz = "0" izz = "0.0000416667" />
    </inertial>
    </link>

  <joint name="joint1" type="revolute">
    <parent link="cube1"/>
    <child link="cube2"/>
    <origin xyz="-0.025 0 0.025" rpy="0 -3.141592 0" />
    <axis xyz="0 1 0" />
    <limit effort="0" lower="-1.5707" upper="1.5707" velocity="0.5"/>
  </joint>

</robot>
