<?xml version="1.0"?>
<robot name="foldable_robot" xmlns:xacro="http://ros.org/wiki/xacro" >
<xacro:property name="pi" value="3.14159265" />

  <material name="red">
    <color rgba="1 0 0 0.3"/>
  </material>

  <material name="blue">
    <color rgba="0 0 1 0.3"/>
  </material>

  <link name="world"/>

  <!--======== Cube 1 =========-->
  <link name="cube1">
    <pose> 0 0 0 0 0 0</pose>

    <inertial>
      <origin
        xyz="0 0 0" rpy="0 0 0" />
      <mass
        value="0.1" />
      <inertia
        ixx="6.023E-05"
        ixy="0"
        ixz="0"
        iyy="7.88E-05"
        iyz="0"
        izz="6.023E-05" />
    </inertial>

    <visual>
      <origin rpy = "0 0 0" xyz = "0 0 0"/>
      <geometry>
        <mesh filename="package://foldable_robot/meshes/cube1.STL" />
      </geometry>
      <material name = "red"/>
    </visual>

    <collision>
      <origin rpy = "0 0 0" xyz = "0 0 0"/>
      <geometry>
        <mesh filename="package://foldable_robot/meshes/cube1.STL" />
      </geometry>
    </collision>
  </link>

  <gazebo reference="cube1">
    <material>Gazebo/Black</material>
  </gazebo>

  <!--======== Cube 2 =========-->
  <link name="cube2">
    <pose> 0 0 0 0 0 0</pose>

    <inertial>
      <origin
        xyz="-0.025 0 0.025" rpy="0 0 0" />
      <mass
        value="0.1" />
      <inertia
        ixx="6.023E-05"
        ixy="0"
        ixz="0"
        iyy="7.88E-05"
        iyz="0"
        izz="6.023E-05" />
    </inertial>

    <visual>
      <origin rpy = "0 0 0" xyz = "-0.05 -0.025 0.05"/>
      <geometry>
        <mesh filename="package://foldable_robot/meshes/cube2.STL" />
      </geometry>
      <material name = "blue"/>
    </visual>

    <collision>
      <origin rpy = "0 0 0" xyz = "-0.05 -0.025 0.05"/>
      <geometry>
        <mesh filename="package://foldable_robot/meshes/cube2.STL" />
      </geometry>
    </collision>
  </link>

  <gazebo reference="cube2">
    <material>Gazebo/Blue</material>
  </gazebo>

  <!--======== Cube 3 =========-->
  <link name="cube3">
    <pose> 0 0 0 0 0 0</pose>

    <inertial>
      <mass value = "0.1" />
      <origin rpy = "0 0 0" xyz = "0 -0.025 -0.025"/>
      <inertia
        ixx="6.023E-05"
        ixy="0"
        ixz="0"
        iyy="7.88E-05"
        iyz="0"
        izz="6.023E-05" />
    </inertial>

    <visual>
      <origin rpy = "0 0 0" xyz = "0.025 -0.05 0"/>
      <geometry>
        <mesh filename="package://foldable_robot/meshes/cube3.STL" />
      </geometry>
      <material name = "red"/>
    </visual>

    <collision>
      <origin rpy = "0 0 0" xyz = "0.025 -0.05 0"/>
      <geometry>
        <mesh filename="package://foldable_robot/meshes/cube3.STL" />
      </geometry>
    </collision>
  </link>

  <gazebo reference="cube3">
    <material>Gazebo/Black</material>
  </gazebo>

  <!--======== Cube 4 =========-->
  <link name="cube4">
    <pose> 0 0 0 0 0 0</pose>

    <inertial>
      <mass value = "0.1" />
      <origin rpy = "0 0 0" xyz = "-0.025 -0.025 0"/>
      <inertia
        ixx="6.023E-05"
        ixy="0"
        ixz="0"
        iyy="7.88E-05"
        iyz="0"
        izz="6.023E-05" />
    </inertial>

    <visual>
      <origin rpy = "0 0 0" xyz = "0 -0.05 0.025"/>
      <geometry>
        <mesh filename="package://foldable_robot/meshes/cube4.STL" />
      </geometry>
      <material name = "blue"/>
    </visual>

    <collision>
      <origin rpy = "0 0 0" xyz = "0 -0.05 0.025"/>
      <geometry>
        <mesh filename="package://foldable_robot/meshes/cube4.STL" />
      </geometry>
    </collision>
  </link>

  <gazebo reference="cube4">
    <material>Gazebo/Blue</material>
  </gazebo>

  <!--======== Cube 5 =========-->
  <link name="cube5">
    <pose> 0 0 0 0 0 0</pose>

    <inertial>
      <mass value = "0.1" />
      <origin rpy = "0 0 0" xyz = "0 -0.025 -0.025"/>
      <inertia
        ixx="6.023E-05"
        ixy="0"
        ixz="0"
        iyy="7.88E-05"
        iyz="0"
        izz="6.023E-05" />
    </inertial>

    <visual>
      <origin rpy = "0 0 0" xyz = "0.025 -0.05 0"/>
      <geometry>
        <mesh filename="package://foldable_robot/meshes/cube5.STL" />
      </geometry>
      <material name = "red"/>
    </visual>

    <collision>
      <origin rpy = "0 0 0" xyz = "0.025 -0.05 0"/>
      <geometry>
        <mesh filename="package://foldable_robot/meshes/cube5.STL" />
      </geometry>
    </collision>
  </link>

  <gazebo reference="cube5">
    <material>Gazebo/Black</material>
  </gazebo>

  <!--======== Cube 6 =========-->
  <link name="cube6">
    <pose> 0 0 0 0 0 0</pose>

    <inertial>
      <mass value = "0.1" />
      <origin rpy = "0 0 0" xyz = "-0.025 0 -0.025"/>
      <inertia
        ixx="6.023E-05"
        ixy="0"
        ixz="0"
        iyy="7.88E-05"
        iyz="0"
        izz="6.023E-05" />
    </inertial>

    <visual>
      <origin rpy = "0 0 0" xyz = "0.0 -0.025 0"/>
      <geometry>
        <mesh filename="package://foldable_robot/meshes/cube6.STL" />
      </geometry>
      <material name = "blue"/>
    </visual>

    <collision>
      <origin rpy = "0 0 0" xyz = "0.0 -0.025 0"/>
      <geometry>
        <mesh filename="package://foldable_robot/meshes/cube6.STL" />
      </geometry>
    </collision>
  </link>

  <gazebo reference="cube6">
    <material>Gazebo/Blue</material>
  </gazebo>

  <!--======== Cube 7 =========-->
  <link name="cube7">
    <pose> 0 0 0 0 0 0</pose>

    <inertial>
      <mass value = "0.1" />
      <origin rpy = "0 0 0" xyz = "0 0.025 0.025"/>
      <inertia
        ixx="6.023E-05"
        ixy="0"
        ixz="0"
        iyy="7.88E-05"
        iyz="0"
        izz="6.023E-05" />
    </inertial>

    <visual>
      <origin rpy = "0 0 0" xyz = "-0.025 0.05 0.05"/>
      <geometry>
        <mesh filename="package://foldable_robot/meshes/cube7.STL" />
      </geometry>
      <material name = "red"/>
    </visual>

    <collision>
      <origin rpy = "0 0 0" xyz = "-0.025 0.05 0.05"/>
      <geometry>
        <mesh filename="package://foldable_robot/meshes/cube7.STL" />
      </geometry>
    </collision>
  </link>

  <gazebo reference="cube7">
    <material>Gazebo/Black</material>
  </gazebo>

  <!--======== Cube 8 =========-->
  <link name="cube8">
    <pose> 0 0 0 0 0 0</pose>

    <inertial>
      <mass value = "0.1" />
      <origin rpy = "0 0 0" xyz = "-0.025 0.025 0"/>
      <inertia
        ixx="6.023E-05"
        ixy="0"
        ixz="0"
        iyy="7.88E-05"
        iyz="0"
        izz="6.023E-05" />
    </inertial>

    <visual>
      <origin rpy = "0 0 0" xyz = "-0.05 0.05 0.025"/>
      <geometry>
        <mesh filename="package://foldable_robot/meshes/cube8.STL" />
      </geometry>
      <material name="blue"/>
    </visual>

    <collision>
      <origin rpy = "0 0 0" xyz = "-0.05 0.05 0.025"/>
      <geometry>
        <mesh filename="package://foldable_robot/meshes/cube8.STL" />
      </geometry>
    </collision>
  </link>

  <gazebo reference="cube8">
    <material>Gazebo/Blue</material>
  </gazebo>

  <!--========== Joints and Transmissions ===========-->
  <joint name="fixed" type="fixed">
    <parent link="world"/>
    <child link="cube1"/>
  </joint>

  <!--======== Joint 1 =========-->
  <joint name="joint1" type="revolute">
    <parent link="cube1"/>
    <child link="cube2"/>
    <origin xyz="-0.025 0 0.025" rpy="0 -1.57 0" />
    <axis xyz="0 1 0" />
    <limit effort="2.5" lower="0.00" upper="3.14" velocity="0.5"/>

  </joint>

  <transmission name="firstJoint">
    <type>transmission_interface/SimpleTransmission</type>

    <actuator name="motor1">
      <hardwareInterface>hardware_interface/PositionJointInterface</hardwareInterface>
      <mechanicalReduction>1</mechanicalReduction>
    </actuator>

    <joint name="joint1">
      <hardwareInterface>hardware_interface/PositionJointInterface</hardwareInterface>
    </joint>
  </transmission>

  <!--======== Joint 2 =========-->
  <joint name="joint2" type="revolute">
    <parent link="cube2"/>
    <child link="cube3"/>
    <origin xyz="-0.025 -0.025 0.05" rpy="0 0 0" />
    <axis xyz="1 0 0" />
    <limit effort="2.5" lower="-3.14" upper="0" velocity="0.5"/>

  </joint>

  <transmission name="secondJoint">
    <type>transmission_interface/SimpleTransmission</type>

    <actuator name="motor2">
      <hardwareInterface>hardware_interface/PositionJointInterface</hardwareInterface>
      <mechanicalReduction>1</mechanicalReduction>
    </actuator>

    <joint name="joint2">
      <hardwareInterface>hardware_interface/PositionJointInterface</hardwareInterface>
    </joint>
  </transmission>

  <!--======== Joint 3 =========-->
  <joint name="joint3" type="revolute">
    <parent link="cube3"/>
    <child link="cube4"/>
    <origin xyz="0.025 -0.05 -0.025" rpy="0 0 0" />
    <axis xyz="0 0 1" />
    <limit effort="2.5" lower="0.0" upper="3.141592" velocity="0.5"/>

  </joint>

  <transmission name="thirdJoint">
    <type>transmission_interface/SimpleTransmission</type>

    <actuator name="motor3">
      <hardwareInterface>hardware_interface/PositionJointInterface</hardwareInterface>
      <mechanicalReduction>1</mechanicalReduction>
    </actuator>

    <joint name="joint3">
      <hardwareInterface>hardware_interface/PositionJointInterface</hardwareInterface>
    </joint>
  </transmission>

  <!--======== Joint 4 =========-->
  <joint name="joint4" type="revolute">
    <parent link="cube4"/>
    <child link="cube5"/>
    <origin xyz="-0.025 -0.05 0.025" rpy="0 0 0" />
    <axis xyz="1 0 0" />
    <limit effort="2.5" lower="-3.141592" upper="0.0" velocity="0.5"/>

  </joint>

  <transmission name="fourthJoint">
    <type>transmission_interface/SimpleTransmission</type>

    <actuator name="motor4">
      <hardwareInterface>hardware_interface/PositionJointInterface</hardwareInterface>
      <mechanicalReduction>1</mechanicalReduction>
    </actuator>

    <joint name="joint4">
      <hardwareInterface>hardware_interface/PositionJointInterface</hardwareInterface>
    </joint>
  </transmission>

  <!--======== Joint 5 =========-->
  <joint name="joint5" type="revolute">
    <parent link="cube5"/>
    <child link="cube6"/>
    <origin xyz="0.025 -0.025 -0.05" rpy="0 0 0" />
    <axis xyz="0 1 0" />
    <limit effort="2.5" lower="-3.141592" upper="0.0" velocity="0.5"/>

  </joint>

  <transmission name="fifthJoint">
    <type>transmission_interface/SimpleTransmission</type>

    <actuator name="motor5">
      <hardwareInterface>hardware_interface/PositionJointInterface</hardwareInterface>
      <mechanicalReduction>1</mechanicalReduction>
    </actuator>

    <joint name="joint5">
      <hardwareInterface>hardware_interface/PositionJointInterface</hardwareInterface>
    </joint>
  </transmission>

  <!--======== Joint 6 =========-->
  <joint name="joint6" type="revolute">
    <parent link="cube6"/>
    <child link="cube7"/>
    <origin xyz="-0.025 0.025 -0.05" rpy="0 0 0" />
    <axis xyz="1 0 0" />
    <limit effort="2.5" lower="-3.141592" upper="0.0" velocity="0.5"/>

  </joint>

  <transmission name="sixthJoint">
    <type>transmission_interface/SimpleTransmission</type>

    <actuator name="motor6">
      <hardwareInterface>hardware_interface/PositionJointInterface</hardwareInterface>
      <mechanicalReduction>1</mechanicalReduction>
    </actuator>

    <joint name="joint6">
      <hardwareInterface>hardware_interface/PositionJointInterface</hardwareInterface>
    </joint>
  </transmission>

  <!--======== Joint 7 =========-->
  <joint name="joint7" type="revolute">
    <parent link="cube7"/>
    <child link="cube8"/>
    <origin xyz="0.025 0.05 0.025" rpy="0 0 0" />
    <axis xyz="0 0 1" />
    <limit effort="2.5" lower="-3.141592" upper="0.0" velocity="0.5"/>

  </joint>

  <transmission name="seventhJoint">
    <type>transmission_interface/SimpleTransmission</type>

    <actuator name="motor7">
      <hardwareInterface>hardware_interface/PositionJointInterface</hardwareInterface>
      <mechanicalReduction>1</mechanicalReduction>
    </actuator>

    <joint name="joint7">
      <hardwareInterface>hardware_interface/PositionJointInterface</hardwareInterface>
    </joint>
  </transmission>

  <!--======== Joint 8 (Gazebo) =========-->
  <gazebo>
    <joint name="joint8" type="revolute">
      <pose relative_to='cube1'>0.025 -0.025 0 0 -0 0</pose>
      <parent>cube8</parent>
      <child>cube1</child>
      <axis>
        <xyz>0 0 1</xyz>
      </axis>
      <limit>
        <lower>-3.141592</lower>
        <upper>0</upper>
        <effort>2.5</effort>
        <velocity>0.5</velocity>
      </limit>
    </joint>
  </gazebo>

  <transmission name="eighthJoint">
    <type>transmission_interface/SimpleTransmission</type>

    <actuator name="motor8">
      <hardwareInterface>hardware_interface/PositionJointInterface</hardwareInterface>
      <mechanicalReduction>1</mechanicalReduction>
    </actuator>

    <joint name="joint8">
      <hardwareInterface>hardware_interface/PositionJointInterface</hardwareInterface>
    </joint>
  </transmission>

  <!-- ROS Control plugin for Gazebo -->
  <gazebo>
    <plugin name="gazebo_ros_control" filename="libgazebo_ros_control.so">
      <!-- <robotNamespace>/foldable_robot</robotNamespace> -->
    </plugin>
    <plugin name="joint_state_publisher" filename="libgazebo_ros_joint_state_publisher.so">
       <jointName>joint1</jointName>
       <updateRate>50.0</updateRate>
       <alwaysOn>true</alwaysOn>
    </plugin>
  </gazebo>

</robot>
