<?xml version="1.0"?>
<robot name="foldable_robot" xmlns:xacro="http://ros.org/wiki/xacro" >
<xacro:property name="pi" value="3.14159265" />

  <material name="red">
    <color rgba="1 0 0 0.3"/>
  </material>

  <material name="blue">
    <color rgba="0 0 1 0.3"/>
  </material>

  <physics type="ode">
    <ode>
      <solver>
        <type>world</type>
      </solver>
      <constraints>
        <contact_max_correcting_vel>0.1</contact_max_correcting_vel>
        <contact_surface_layer>0.0001</contact_surface_layer>
      </constraints>
    </ode>
    <max_step_size>0.001</max_step_size>
  </physics>

  <gravity>0.0 0.0 -9.81</gravity>

  <!-- <link name="world"/> -->

  <!--======== Cube 1 =========-->
  <link name="cube1">
    <pose> 0 0 0 0 0 0</pose>

    <inertial>
      <origin
        xyz="0 0 0" rpy="0 0 0" />
      <mass
        value="0.1" />
      <inertia
        ixx="6.023E-05"
        ixy="0"
        ixz="0"
        iyy="7.88E-05"
        iyz="0"
        izz="6.023E-05" />
    </inertial>

    <visual>
      <origin rpy = "0 0 0" xyz = "0 0 0"/>
      <geometry>
        <mesh filename="package://foldable_robot/meshes/cube1.STL" />
      </geometry>
      <material name = "red"/>
    </visual>

    <collision>
      <origin rpy = "0 0 0" xyz = "0 0 0"/>
      <geometry>
        <mesh filename="package://foldable_robot/meshes/cube1.STL" />
      </geometry>

      <surface>
        <friction>
          <ode>
            <mu>0.2</mu>
            <mu2>0.2</mu2>
            <fdir1>0 0 0</fdir1>
            <slip1>0</slip1>
            <slip2>0</slip2>
          </ode>
        </friction>
        <bounce>
          <restitution_coefficient>0.0</restitution_coefficient>
          <threshold>100000.0</threshold>
        </bounce>
        <contact>
          <ode>
            <soft_cfm>0.0</soft_cfm>
            <soft_erp>0.2</soft_erp>
            <kp>1000000.0</kp>
            <kd>1</kd>
            <max_vel>0.0</max_vel>
            <min_depth>0.00</min_depth>
          </ode>
        </contact>
      </surface>

    </collision>
  </link>

  <gazebo reference="cube1">
    <material>Gazebo/Black</material>
  </gazebo>

  <!--======== Cube 2 =========-->
  <link name="cube2">
    <pose> 0 0 0 0 0 0</pose>

    <inertial>
      <origin
        xyz="-0.025 0 0.025" rpy="0 0 0" />
      <mass
        value="0.1" />
      <inertia
        ixx="6.023E-05"
        ixy="0"
        ixz="0"
        iyy="7.88E-05"
        iyz="0"
        izz="6.023E-05" />
    </inertial>

    <visual>
      <origin rpy = "0 0 0" xyz = "-0.05 -0.025 0.05"/>
      <geometry>
        <mesh filename="package://foldable_robot/meshes/cube2.STL" />
      </geometry>
      <material name = "blue"/>
    </visual>

    <collision>
      <origin rpy = "0 0 0" xyz = "-0.05 -0.025 0.05"/>
      <geometry>
        <mesh filename="package://foldable_robot/meshes/cube2.STL" />
      </geometry>

      <surface>
        <friction>
          <ode>
            <mu>0.2</mu>
            <mu2>0.2</mu2>
            <fdir1>0 0 0</fdir1>
            <slip1>0</slip1>
            <slip2>0</slip2>
          </ode>
        </friction>
        <bounce>
          <restitution_coefficient>0.0</restitution_coefficient>
          <threshold>100000.0</threshold>
        </bounce>
        <contact>
          <ode>
            <soft_cfm>0.0</soft_cfm>
            <soft_erp>0.2</soft_erp>
            <kp>1000000.0</kp>
            <kd>1</kd>
            <max_vel>0.0</max_vel>
            <min_depth>0.00</min_depth>
          </ode>
        </contact>
      </surface>

    </collision>
  </link>

  <gazebo reference="cube2">
    <material>Gazebo/Blue</material>
  </gazebo>

  <!--======== Cube 3 =========-->
  <link name="cube3">
    <pose> 0 0 0 0 0 0</pose>

    <inertial>
      <mass value = "0.1" />
      <origin rpy = "0 0 0" xyz = "0 -0.025 -0.025"/>
      <inertia
        ixx="6.023E-05"
        ixy="0"
        ixz="0"
        iyy="7.88E-05"
        iyz="0"
        izz="6.023E-05" />
    </inertial>

    <visual>
      <origin rpy = "0 0 0" xyz = "0.025 -0.05 0"/>
      <geometry>
        <mesh filename="package://foldable_robot/meshes/cube3.STL" />
      </geometry>
      <material name = "red"/>
    </visual>

    <collision>
      <origin rpy = "0 0 0" xyz = "0.025 -0.05 0"/>
      <geometry>
        <mesh filename="package://foldable_robot/meshes/cube3.STL" />
      </geometry>

      <surface>
        <friction>
          <ode>
            <mu>0.2</mu>
            <mu2>0.2</mu2>
            <fdir1>0 0 0</fdir1>
            <slip1>0</slip1>
            <slip2>0</slip2>
          </ode>
        </friction>
        <bounce>
          <restitution_coefficient>0.0</restitution_coefficient>
          <threshold>100000.0</threshold>
        </bounce>
        <contact>
          <ode>
            <soft_cfm>0.0</soft_cfm>
            <soft_erp>0.2</soft_erp>
            <kp>1000000.0</kp>
            <kd>1</kd>
            <max_vel>0.0</max_vel>
            <min_depth>0.00</min_depth>
          </ode>
        </contact>
      </surface>

    </collision>
  </link>

  <gazebo reference="cube3">
    <material>Gazebo/Black</material>
  </gazebo>

  <!--======== Cube 4 =========-->
  <link name="cube4">
    <pose> 0 0 0 0 0 0</pose>

    <inertial>
      <mass value = "0.1" />
      <origin rpy = "0 0 0" xyz = "-0.025 -0.025 0"/>
      <inertia
        ixx="6.023E-05"
        ixy="0"
        ixz="0"
        iyy="7.88E-05"
        iyz="0"
        izz="6.023E-05" />
    </inertial>

    <visual>
      <origin rpy = "0 0 0" xyz = "0 -0.05 0.025"/>
      <geometry>
        <mesh filename="package://foldable_robot/meshes/cube4.STL" />
      </geometry>
      <material name = "blue"/>
    </visual>

    <collision>
      <origin rpy = "0 0 0" xyz = "0 -0.05 0.025"/>
      <geometry>
        <mesh filename="package://foldable_robot/meshes/cube4.STL" />
      </geometry>

      <surface>
        <friction>
          <ode>
            <mu>0.2</mu>
            <mu2>0.2</mu2>
            <fdir1>0 0 0</fdir1>
            <slip1>0</slip1>
            <slip2>0</slip2>
          </ode>
        </friction>
        <bounce>
          <restitution_coefficient>0.0</restitution_coefficient>
          <threshold>100000.0</threshold>
        </bounce>
        <contact>
          <ode>
            <soft_cfm>0.0</soft_cfm>
            <soft_erp>0.2</soft_erp>
            <kp>1000000.0</kp>
            <kd>1</kd>
            <max_vel>0.0</max_vel>
            <min_depth>0.00</min_depth>
          </ode>
        </contact>
      </surface>

    </collision>
  </link>

  <gazebo reference="cube4">
    <material>Gazebo/Blue</material>
  </gazebo>

  <!--======== Cube 5 =========-->
  <link name="cube5">
    <pose> 0 0 0 0 0 0</pose>

    <inertial>
      <mass value = "0.1" />
      <origin rpy = "0 0 0" xyz = "0 -0.025 -0.025"/>
      <inertia
        ixx="6.023E-05"
        ixy="0"
        ixz="0"
        iyy="7.88E-05"
        iyz="0"
        izz="6.023E-05" />
    </inertial>

    <visual>
      <origin rpy = "0 0 0" xyz = "0.025 -0.05 0"/>
      <geometry>
        <mesh filename="package://foldable_robot/meshes/cube5.STL" />
      </geometry>
      <material name = "red"/>
    </visual>

    <collision>
      <origin rpy = "0 0 0" xyz = "0.025 -0.05 0"/>
      <geometry>
        <mesh filename="package://foldable_robot/meshes/cube5.STL" />
      </geometry>

      <surface>
        <friction>
          <ode>
            <mu>0.2</mu>
            <mu2>0.2</mu2>
            <fdir1>0 0 0</fdir1>
            <slip1>0</slip1>
            <slip2>0</slip2>
          </ode>
        </friction>
        <bounce>
          <restitution_coefficient>0.0</restitution_coefficient>
          <threshold>100000.0</threshold>
        </bounce>
        <contact>
          <ode>
            <soft_cfm>0.0</soft_cfm>
            <soft_erp>0.2</soft_erp>
            <kp>1000000.0</kp>
            <kd>1</kd>
            <max_vel>0.0</max_vel>
            <min_depth>0.00</min_depth>
          </ode>
        </contact>
      </surface>

    </collision>
  </link>

  <gazebo reference="cube5">
    <material>Gazebo/Black</material>
  </gazebo>

  <!--======== Cube 6 =========-->
  <link name="cube6">
    <pose> 0 0 0 0 0 0</pose>

    <inertial>
      <mass value = "0.1" />
      <origin rpy = "0 0 0" xyz = "-0.025 0 -0.025"/>
      <inertia
        ixx="6.023E-05"
        ixy="0"
        ixz="0"
        iyy="7.88E-05"
        iyz="0"
        izz="6.023E-05" />
    </inertial>

    <visual>
      <origin rpy = "0 0 0" xyz = "0.0 -0.025 0"/>
      <geometry>
        <mesh filename="package://foldable_robot/meshes/cube6.STL" />
      </geometry>
      <material name = "blue"/>
    </visual>

    <collision>
      <origin rpy = "0 0 0" xyz = "0.0 -0.025 0"/>
      <geometry>
        <mesh filename="package://foldable_robot/meshes/cube6.STL" />
      </geometry>

      <surface>
        <friction>
          <ode>
            <mu>0.2</mu>
            <mu2>0.2</mu2>
            <fdir1>0 0 0</fdir1>
            <slip1>0</slip1>
            <slip2>0</slip2>
          </ode>
        </friction>
        <bounce>
          <restitution_coefficient>0.0</restitution_coefficient>
          <threshold>100000.0</threshold>
        </bounce>
        <contact>
          <ode>
            <soft_cfm>0.0</soft_cfm>
            <soft_erp>0.2</soft_erp>
            <kp>1000000.0</kp>
            <kd>1</kd>
            <max_vel>0.0</max_vel>
            <min_depth>0.00</min_depth>
          </ode>
        </contact>
      </surface>

    </collision>
  </link>

  <gazebo reference="cube6">
    <material>Gazebo/Blue</material>
  </gazebo>

  <!--======== Cube 7 =========-->
  <link name="cube7">
    <pose> 0 0 0 0 0 0</pose>

    <inertial>
      <mass value = "0.1" />
      <origin rpy = "0 0 0" xyz = "0 0.025 0.025"/>
      <inertia
        ixx="6.023E-05"
        ixy="0"
        ixz="0"
        iyy="7.88E-05"
        iyz="0"
        izz="6.023E-05" />
    </inertial>

    <visual>
      <origin rpy = "0 0 0" xyz = "-0.025 0.05 0.05"/>
      <geometry>
        <mesh filename="package://foldable_robot/meshes/cube7.STL" />
      </geometry>
      <material name = "red"/>
    </visual>

    <collision>
      <origin rpy = "0 0 0" xyz = "-0.025 0.05 0.05"/>
      <geometry>
        <mesh filename="package://foldable_robot/meshes/cube7.STL" />
      </geometry>

      <surface>
        <friction>
          <ode>
            <mu>0.2</mu>
            <mu2>0.2</mu2>
            <fdir1>0 0 0</fdir1>
            <slip1>0</slip1>
            <slip2>0</slip2>
          </ode>
        </friction>
        <bounce>
          <restitution_coefficient>0.0</restitution_coefficient>
          <threshold>100000.0</threshold>
        </bounce>
        <contact>
          <ode>
            <soft_cfm>0.0</soft_cfm>
            <soft_erp>0.2</soft_erp>
            <kp>1000000.0</kp>
            <kd>1</kd>
            <max_vel>0.0</max_vel>
            <min_depth>0.00</min_depth>
          </ode>
        </contact>
      </surface>

    </collision>
  </link>

  <gazebo reference="cube7">
    <material>Gazebo/Black</material>
  </gazebo>

  <!--======== Cube 8 =========-->
  <link name="cube8">
    <pose> 0 0 0 0 0 0</pose>

    <inertial>
      <mass value = "0.1" />
      <origin rpy = "0 0 0" xyz = "-0.025 0.025 0"/>
      <inertia
        ixx="6.023E-05"
        ixy="0"
        ixz="0"
        iyy="7.88E-05"
        iyz="0"
        izz="6.023E-05" />
    </inertial>

    <visual>
      <origin rpy = "0 0 0" xyz = "-0.05 0.05 0.025"/>
      <geometry>
        <mesh filename="package://foldable_robot/meshes/cube8.STL" />
      </geometry>
      <material name="blue"/>
    </visual>

    <collision>
      <origin rpy = "0 0 0" xyz = "-0.05 0.05 0.025"/>
      <geometry>
        <mesh filename="package://foldable_robot/meshes/cube8.STL" />
      </geometry>

      <surface>
        <friction>
          <ode>
            <mu>0.2</mu>
            <mu2>0.2</mu2>
            <fdir1>0 0 0</fdir1>
            <slip1>0</slip1>
            <slip2>0</slip2>
          </ode>
        </friction>
        <bounce>
          <restitution_coefficient>0.0</restitution_coefficient>
          <threshold>100000.0</threshold>
        </bounce>
        <contact>
          <ode>
            <soft_cfm>0.0</soft_cfm>
            <soft_erp>0.2</soft_erp>
            <kp>1000000.0</kp>
            <kd>1</kd>
            <max_vel>0.0</max_vel>
            <min_depth>0.00</min_depth>
          </ode>
        </contact>
      </surface>

    </collision>
  </link>

  <gazebo reference="cube8">
    <material>Gazebo/Blue</material>
  </gazebo>

  <!--========== Joints and Transmissions ===========-->
  <!--
  <joint name="fixed" type="fixed">
    <parent link="world"/>
    <child link="cube1"/>
  </joint>
  -->
  <!--======== Joint 1 =========-->
  <joint name="joint1" type="revolute">
    <parent link="cube1"/>
    <child link="cube2"/>
    <origin xyz="-0.025 0 0.025" rpy="0 -1.57 0" />
    <axis xyz="0 1 0" />
    <limit effort="1" lower="0.00" upper="3.14" velocity="0.5"/>

  </joint>

  <transmission name="firstJoint">
    <type>transmission_interface/SimpleTransmission</type>

    <actuator name="motor1">
      <hardwareInterface>hardware_interface/PositionJointInterface</hardwareInterface>
      <mechanicalReduction>1</mechanicalReduction>
    </actuator>

    <joint name="joint1">
      <hardwareInterface>hardware_interface/PositionJointInterface</hardwareInterface>
    </joint>
  </transmission>

  <!--======== Joint 2 =========-->
  <joint name="joint2" type="revolute">
    <parent link="cube2"/>
    <child link="cube3"/>
    <origin xyz="-0.025 -0.025 0.05" rpy="0 0 0" />
    <axis xyz="1 0 0" />
    <limit effort="1" lower="-3.14" upper="0" velocity="0.5"/>

  </joint>

  <transmission name="secondJoint">
    <type>transmission_interface/SimpleTransmission</type>

    <actuator name="motor2">
      <hardwareInterface>hardware_interface/PositionJointInterface</hardwareInterface>
      <mechanicalReduction>1</mechanicalReduction>
    </actuator>

    <joint name="joint2">
      <hardwareInterface>hardware_interface/PositionJointInterface</hardwareInterface>
    </joint>
  </transmission>

  <!--======== Joint 3 =========-->
  <joint name="joint3" type="revolute">
    <parent link="cube3"/>
    <child link="cube4"/>
    <origin xyz="0.025 -0.05 -0.025" rpy="0 0 0" />
    <axis xyz="0 0 1" />
    <limit effort="1" lower="0.0" upper="3.141592" velocity="0.5"/>

  </joint>

  <transmission name="thirdJoint">
    <type>transmission_interface/SimpleTransmission</type>

    <actuator name="motor3">
      <hardwareInterface>hardware_interface/PositionJointInterface</hardwareInterface>
      <mechanicalReduction>1</mechanicalReduction>
    </actuator>

    <joint name="joint3">
      <hardwareInterface>hardware_interface/PositionJointInterface</hardwareInterface>
    </joint>
  </transmission>

  <!--======== Joint 4 =========-->
  <joint name="joint4" type="revolute">
    <parent link="cube4"/>
    <child link="cube5"/>
    <origin xyz="-0.025 -0.05 0.025" rpy="0 0 0" />
    <axis xyz="1 0 0" />
    <limit effort="1" lower="-3.141592" upper="0.0" velocity="0.5"/>

  </joint>

  <!--======== Joint 5 =========-->
  <joint name="joint5" type="revolute">
    <parent link="cube5"/>
    <child link="cube6"/>
    <origin xyz="0.025 -0.025 -0.05" rpy="0 0 0" />
    <axis xyz="0 1 0" />
    <limit effort="1" lower="-3.141592" upper="0.0" velocity="0.5"/>

  </joint>

  <!--======== Joint 6 =========-->
  <joint name="joint6" type="revolute">
    <parent link="cube6"/>
    <child link="cube7"/>
    <origin xyz="-0.025 0.025 -0.05" rpy="0 0 0" />
    <axis xyz="1 0 0" />
    <limit effort="1" lower="-3.141592" upper="0.0" velocity="0.5"/>

  </joint>

  <transmission name="sixthJoint">
    <type>transmission_interface/SimpleTransmission</type>

    <actuator name="motor6">
      <hardwareInterface>hardware_interface/PositionJointInterface</hardwareInterface>
      <mechanicalReduction>1</mechanicalReduction>
    </actuator>

    <joint name="joint6">
      <hardwareInterface>hardware_interface/PositionJointInterface</hardwareInterface>
    </joint>
  </transmission>

  <!--======== Joint 7 =========-->
  <joint name="joint7" type="revolute">
    <parent link="cube7"/>
    <child link="cube8"/>
    <origin xyz="0.025 0.05 0.025" rpy="0 0 0" />
    <axis xyz="0 0 1" />
    <limit effort="1" lower="-3.141592" upper="0.0" velocity="0.5"/>

  </joint>

  <!--======== Joint 8 (Gazebo) =========-->
  <gazebo>
    <joint name="joint8" type="revolute">
      <pose relative_to='cube1'>0.025 -0.025 0 0 -0 0</pose>
      <parent>cube8</parent>
      <child>cube1</child>
      <axis>
        <xyz>0 0 1</xyz>
      </axis>
      <limit>
        <lower>-3.141592</lower>
        <upper>0</upper>
        <effort>1</effort>
        <velocity>0.5</velocity>
      </limit>
    </joint>
  </gazebo>

  <transmission name="eighthJoint">
    <type>transmission_interface/SimpleTransmission</type>

    <actuator name="motor8">
      <hardwareInterface>hardware_interface/PositionJointInterface</hardwareInterface>
      <mechanicalReduction>1</mechanicalReduction>
    </actuator>

    <joint name="joint8">
      <hardwareInterface>hardware_interface/PositionJointInterface</hardwareInterface>
    </joint>
  </transmission>

  <!--========= Servos ===========-->
  <link name="servo1">
    <inertial>
      <origin
        xyz="0 0 0" rpy="0 0 0" />
      <mass
        value="0.025" />
      <inertia
        ixx="0.0000009375"
        ixy="0"
        ixz="0"
        iyy="0.0000009375"
        iyz="0"
        izz="0.0000009375" />
    </inertial>

    <visual>
      <origin rpy = "0 0 0" xyz = "0 0 0"/>
      <geometry>
        <box size = "0.015 0.015 0.015"/>
      </geometry>
      <material name = "red"/>
    </visual>
  </link>

  <joint name="jointservo1" type="revolute">
    <parent link="cube2"/>
    <child link="servo1"/>
    <origin xyz="0 0 0" rpy="0 0 0" />
    <axis xyz="0 0 1" />
    <limit effort="0" lower="0.0" upper="0.0" velocity="0"/>
  </joint>

  <link name="servo2">
    <inertial>
      <origin
        xyz="0 0 0" rpy="0 0 0" />
      <mass
        value="0.025" />
      <inertia
        ixx="0.0000009375"
        ixy="0"
        ixz="0"
        iyy="0.0000009375"
        iyz="0"
        izz="0.0000009375" />
    </inertial>

    <visual>
      <origin rpy = "0 0 0" xyz = "0 0 0"/>
      <geometry>
        <box size = "0.015 0.015 0.015"/>
      </geometry>
      <material name = "red"/>
    </visual>
  </link>

  <joint name="jointservo2" type="revolute">
    <parent link="cube3"/>
    <child link="servo2"/>
    <origin xyz="0 0 0" rpy="0 0 0" />
    <axis xyz="0 0 1" />
    <limit effort="0" lower="0.0" upper="0.0" velocity="0"/>
  </joint>

  <link name="servo3">
    <inertial>
      <origin
        xyz="0 0 0" rpy="0 0 0" />
      <mass
        value="0.025"/>
      <inertia
        ixx="0.0000009375"
        ixy="0"
        ixz="0"
        iyy="0.0000009375"
        iyz="0"
        izz="0.0000009375" />
    </inertial>

    <visual>
      <origin rpy = "0 0 0" xyz = "0 0 0"/>
      <geometry>
        <box size = "0.015 0.015 0.015"/>
      </geometry>
      <material name = "red"/>
    </visual>
  </link>

  <joint name="jointservo3" type="revolute">
    <parent link="cube4"/>
    <child link="servo3"/>
    <origin xyz="0 0 0" rpy="0 0 0" />
    <axis xyz="0 0 1" />
    <limit effort="0" lower="0.0" upper="0.0" velocity="0"/>
  </joint>

  <link name="servo4">
    <inertial>
      <origin
        xyz="0 0 0" rpy="0 0 0" />
      <mass
        value="0.025" />
      <inertia
        ixx="0.0000009375"
        ixy="0"
        ixz="0"
        iyy="0.0000009375"
        iyz="0"
        izz="0.0000009375" />
    </inertial>

    <visual>
      <origin rpy = "0 0 0" xyz = "0 0 0"/>
      <geometry>
        <box size = "0.015 0.015 0.015"/>
      </geometry>
      <material name = "red"/>
    </visual>
  </link>

  <joint name="jointservo4" type="revolute">
    <parent link="cube7"/>
    <child link="servo4"/>
    <origin xyz="0 0 0" rpy="0 0 0" />
    <axis xyz="0 0 1" />
    <limit effort="0" lower="0.0" upper="0.0" velocity="0"/>
  </joint>

  <link name="servo5">
    <inertial>
      <origin
        xyz="0 0 0" rpy="0 0 0" />
      <mass
        value="0.025" />
      <inertia
        ixx="0.0000009375"
        ixy="0"
        ixz="0"
        iyy="0.0000009375"
        iyz="0"
        izz="0.0000009375" />
    </inertial>

    <visual>
      <origin rpy = "0 0 0" xyz = "0 0 0"/>
      <geometry>
        <box size = "0.015 0.015 0.015"/>
      </geometry>
      <material name = "red"/>
    </visual>
  </link>

  <joint name="jointservo5" type="revolute">
    <parent link="cube8"/>
    <child link="servo5"/>
    <origin xyz="-0.025 0.05 -0.025" rpy="0 0 0" />
    <axis xyz="0 0 1" />
    <limit effort="0" lower="0.0" upper="0.0" velocity="0"/>
  </joint>

  <!-- ROS Control plugin for Gazebo -->
  <gazebo>
    <plugin name="gazebo_ros_control" filename="libgazebo_ros_control.so">
      <!-- <robotNamespace>/foldable_robot</robotNamespace> -->
    </plugin>
      <!--
       <plugin name="joint_state_publisher" filename="libgazebo_ros_joint_state_publisher.so">
       <jointName>joint1</jointName>
       <updateRate>50.0</updateRate>
       <alwaysOn>true</alwaysOn>
       </plugin>
      -->
  </gazebo>

</robot>
